Workbook
Name Slicer_ALAMAT: #N/A

Sheet DATA PENDUDUK
A1: DATA PENDUDUK KAMPUNG KADUN JAYA
A3: NO | B3: NO. KK | C3: NIK | D3: NAMA | E3: JENIS KELAMIN | F3: TEMPAT LAHIR | G3: TANGGAL LAHIR | H3: AGAMA | I3: PEKERJAAN | J3: STATUS DLM KELUARGA | K3: UMUR | L3: ALAMAT
A4: =IF(D4="","",ROW()-3) -> 1 | B4: 9109012701120047 | C4: 9109011907860010 | D4: ABRAHAM WEMAF | E4: LAKI-LAKI | F4: OHOINOL | G4: 31612 | H4: KATHOLIK | I4: WIRASWASTA | J4: KEPALA KELUARGA | K4: =DATEDIF('DATA PENDUDUK'!$G4,TODAY(),"Y")& " TAHUN" -> 39 TAHUN | L4: RT 01
A5: =IF(D5="","",ROW()-3) -> 2 | B5: 9109012701120047 | C5: 9109014808750011 | D5: PAULA SUSYANA | E5: PEREMPUAN | F5: BANYUWANGI | G5: 27614 | H5: KATHOLIK | I5: IRT | J5: ISTRI | K5: =DATEDIF('DATA PENDUDUK'!$G5,TODAY(),"Y")& " TAHUN" -> 49 TAHUN | L5: RT 01
A6: =IF(D6="","",ROW()-3) -> 3 | B6: 9109012701120047 | C6: 9109164711120001 | D6: DIAH AYU CANTIKA WEMAF | E6: PEREMPUAN | F6: TIMIKA | G6: 41220 | H6: KATHOLIK | I6: PELAJAR/MAHASISWA | J6: ANAK | K6: =DATEDIF('DATA PENDUDUK'!$G6,TODAY(),"Y")& " TAHUN" -> 12 TAHUN | L6: RT 01
A7: =IF(D7="","",ROW()-3) -> 4 | B7: 9109012701120047 | C7: 3510245010820001 | D7: MASRIYANI | E7: PEREMPUAN | F7: BANYUWANGI | G7: 30234 | H7: ISLAM | I7: PETANI | J7: FAMILI LAIN | K7: =DATEDIF('DATA PENDUDUK'!$G7,TODAY(),"Y")& " TAHUN" -> 42 TAHUN | L7: RT 01
A8: =IF(D8="","",ROW()-3) -> 5 | B8: 9109012701120047 | C8: 8102134809940001 | D8: KRESENSIA FABUMASE | E8: PEREMPUAN | F8: OHOINOL | G8: 34585 | H8: KATHOLIK | I8: BELUM/TIDAK BEKERJA | J8: FAMILI LAIN | K8: =DATEDIF('DATA PENDUDUK'!$G8,TODAY(),"Y")& " TAHUN" -> 30 TAHUN | L8: RT 01
A9: =IF(D9="","",ROW()-3) -> 6 | B9: 9109012701120047 | C9: 8102134307040001 | D9: FELOMENA MARSELINA WEMAF | E9: PEREMPUAN | F9: OHOINOL | G9: 38171 | H9: KATHOLIK | I9: BELUM/TIDAK BEKERJA | J9: FAMILI LAIN | K9: =DATEDIF('DATA PENDUDUK'!$G9,TODAY(),"Y")& " TAHUN" -> 21 TAHUN | L9: RT 01
A10: =IF(D10="","",ROW()-3) -> 7 | B10: 9109013110110049 | C10: 9109091804800004 | D10: MAS'UD | E10: LAKI-LAKI | F10: LAMONGAN | G10: 29329 | H10: ISLAM | I10: WIRASWASTA | J10: KEPALA KELUARGA | K10: =DATEDIF('DATA PENDUDUK'!$G10,TODAY(),"Y")& " TAHUN" -> 45 TAHUN | L10: RT 01
A11: =IF(D11="","",ROW()-3) -> 8 | B11: 9109013110110049 | C11: 3504115807990005 | D11: MIRA ROSA AMARINDA | E11: PEREMPUAN | F11: TULUNGAGUNG | G11: 36359 | H11: ISLAM | I11: PELAJAR/MAHASISWA | J11: FAMILI LAIN | K11: =DATEDIF('DATA PENDUDUK'!$G11,TODAY(),"Y")& " TAHUN" -> 26 TAHUN | L11: RT 01
A12: =IF(D12="","",ROW()-3) -> 9 | B12: 9404162305250007 | C12: 3524090111930002 | D12: HABIB RUSLI | E12: LAKI-LAKI | F12: LAMONGAN | G12: 34095 | H12: ISLAM | I12: WIRASWASTA | J12: KEPALA KELUARGA | K12: =DATEDIF('DATA PENDUDUK'!$G12,TODAY(),"Y")& " TAHUN" -> 32 TAHUN | L12: RT 01
A13: =IF(D13="","",ROW()-3) -> 10 | B13: 9404162305250007 | C13: 3524095009150002 | D13: ADEEVA MAHARA PUTRI KHABILA | E13: PEREMPUAN | F13: LAMONGAN | G13: 42257 | H13: ISLAM | I13: BELUM/TIDAK BEKERJA | J13: ANAK | K13: =DATEDIF('DATA PENDUDUK'!$G13,TODAY(),"Y")& " TAHUN" -> 9 TAHUN | L13: RT 01
A14: =IF(D14="","",ROW()-3) -> 11 | B14: 9404160809230002 | C14: 9109035509750001 | D14: HANA | E14: PEREMPUAN | F14: PURWODADI | G14: 27652 | H14: ISLAM | I14: WIRASWASTA | J14: KEPALA KELUARGA | K14: =DATEDIF('DATA PENDUDUK'!$G14,TODAY(),"Y")& " TAHUN" -> 49 TAHUN | L14: RT 01
A15: =IF(D15="","",ROW()-3) -> 12 | B15: 9404160809230002 | C15: 9109035808670002 | D15: KUSTINI | E15: PEREMPUAN | F15: SITUBONDO | G15: 32007 | H15: ISLAM | I15: WIRASWASTA | J15: FAMILI LAIN | K15: =DATEDIF('DATA PENDUDUK'!$G15,TODAY(),"Y")& " TAHUN" -> 37 TAHUN | L15: RT 01
... A1213: =IF(D1213="","",ROW()-3) -> 1210 | B1213: 9109162408210003 | C1213: 9108014401900007 | D1213: DEVI TRI SUSANTI | E1213: PEREMPUAN | F1213: LAMONGAN | G1213: 32877 | H1213: ISLAM | I1213: PERAWAT | J1213: FAMILI LAIN | K1213: =DATEDIF('DATA PENDUDUK'!$G1213,TODAY(),"Y")& " TAHUN" -> 35 TAHUN | L1213: RT 08
A1214: =IF(D1214="","",ROW()-3) -> 1211 | B1214: 9404162807230003 | C1214: 9104011705940007 | D1214: KAISANUS PIGAI | E1214: LAKI-LAKI | G1214: 34471 | H1214: KATHOLIK | I1214: TENTARA NASIONAL INDONESIA (TNI) | J1214: KEPALA KELUARGA | K1214: =DATEDIF('DATA PENDUDUK'!$G1214,TODAY(),"Y")& " TAHUN" -> 31 TAHUN | L1214: RT 08
A1215: =IF(D1215="","",ROW()-3) -> 1212 | B1215: 9404162807230003 | C1215: 9109015208970003 | D1215: AGUSTINA MAGAI | E1215: PEREMPUAN | F1215: TIMIKA | G1215: 35654 | H1215: KATHOLIK | I1215: BELUM/TIDAK BEKERJA | J1215: ISTRI | K1215: =DATEDIF('DATA PENDUDUK'!$G1215,TODAY(),"Y")& " TAHUN" -> 27 TAHUN | L1215: RT 08
A1216: =IF(D1216="","",ROW()-3) -> 1213 | B1216: 9404162807230003 | C1216: 9404161709230001 | D1216: JHON LUCKY PIGAI | E1216: LAKI-LAKI | F1216: TIMIKA | G1216: 45186 | H1216: KATHOLIK | I1216: BELUM/TIDAK BEKERJA | J1216: ANAK | K1216: =DATEDIF('DATA PENDUDUK'!$G1216,TODAY(),"Y")& " TAHUN" -> 1 TAHUN | L1216: RT 08
A1217: =IF(D1217="","",ROW()-3) -> 1214 | B1217: 9109030702130001 | C1217: 9109030202900001 | D1217: PUNGKI HARI PAMUNGKAS | E1217: LAKI-LAKI | F1217: JEMBER | G1217: 32906 | H1217: ISLAM | I1217: TENTARA NASIONAL INDONESIA (TNI) | J1217: KEPALA KELUARGA | K1217: =DATEDIF('DATA PENDUDUK'!$G1217,TODAY(),"Y")& " TAHUN" -> 35 TAHUN | L1217: RT 08
A1218: =IF(D1218="","",ROW()-3) -> 1215 | B1218: 9109030702130001 | C1218: 9109015610890002 | D1218: SITI NURJANAH | E1218: PEREMPUAN | F1218: PENAWANGAN GROBOGAN | G1218: 32795 | H1218: ISLAM | I1218: MENGURUS RUMAH TANGGA | J1218: ISTRI | K1218: =DATEDIF('DATA PENDUDUK'!$G1218,TODAY(),"Y")& " TAHUN" -> 35 TAHUN | L1218: RT 08
A1219: =IF(D1219="","",ROW()-3) -> 1216 | B1219: 9109030702130001 | C1219: 9109037101130001 | D1219: AZHAKIRA MUTIARA KIRANA | E1219: PEREMPUAN | F1219: TIMIKA | G1219: 41305 | H1219: ISLAM | I1219: PELAJAR/MAHASISWA | J1219: ANAK | K1219: =DATEDIF('DATA PENDUDUK'!$G1219,TODAY(),"Y")& " TAHUN" -> 12 TAHUN | L1219: RT 08
A1220: =IF(D1220="","",ROW()-3) -> 1217 | B1220: 9109030702130001 | C1220: 9109166910170001 | D1220: ADINDA TASYA PAMUNGKAS | E1220: PEREMPUAN | F1220: SIDOARJO | G1220: 43037 | H1220: ISLAM | I1220: BELUM/TIDAK BEKERJA | J1220: ANAK | K1220: =DATEDIF('DATA PENDUDUK'!$G1220,TODAY(),"Y")& " TAHUN" -> 7 TAHUN | L1220: RT 08
A1221: =IF(D1221="","",ROW()-3) -> 1218 | B1221: 9404160203230001 | C1221: 3524223004960003 | D1221: FAUZI KRISNAWAN HARTONO | E1221: LAKI-LAKI | F1221: MAKASAR | G1221: 35185 | H1221: ISLAM | I1221: TENTARA NASIONAL INDONESIA (TNI) | J1221: KEPALA KELUARGA | K1221: =DATEDIF('DATA PENDUDUK'!$G1221,TODAY(),"Y")& " TAHUN" -> 29 TAHUN | L1221: RT 08
A1222: =IF(D1222="","",ROW()-3) -> 1219 | B1222: 9404160203230001 | C1222: 3524174203950001 | D1222: GLADIS VELLA NOVIYANTI | E1222: PEREMPUAN | F1222: LAMONGAN | G1222: 34778 | H1222: ISLAM | I1222: BELUM/TIDAK BEKERJA | J1222: ISTRI | K1222: =DATEDIF('DATA PENDUDUK'!$G1222,TODAY(),"Y")& " TAHUN" -> 30 TAHUN | L1222: RT 08
A1223: =IF(D1223="","",ROW()-3) -> 1220 | B1223: 9109162010160011 | C1223: 7308221612920002 | D1223: YUSWANDI | E1223: LAKI-LAKI | F1223: WATAMPONE | G1223: 33954 | H1223: ISLAM | I1223: TENTARA NASIONAL INDONESIA (TNI) | J1223: KEPALA KELUARGA | K1223: =DATEDIF('DATA PENDUDUK'!$G1223,TODAY(),"Y")& " TAHUN" -> 32 TAHUN | L1223: RT 08
A1224: =IF(D1224="","",ROW()-3) -> 1221 | B1224: 9109162010160011 | C1224: 9109015708000012 | D1224: PUTRI MILANI SYAM BOKKO | E1224: PEREMPUAN | F1224: BOMBONAWULU | G1224: 36877 | H1224: ISLAM | I1224: MENGURUS RUMAH TANGGA | J1224: ISTRI | K1224: =DATEDIF('DATA PENDUDUK'!$G1224,TODAY(),"Y")& " TAHUN" -> 24 TAHUN | L1224: RT 08
A1225: =IF(D1225="","",ROW()-3) -> 1222 | B1225: 9109162010160011 | C1225: 9109162903220001 | D1225: ARGANTARA MARENDRA PERKASA | E1225: LAKI-LAKI | F1225: TIMIKA | G1225: 44649 | H1225: ISLAM | I1225: BELUM/TIDAK BEKERJA | J1225: ANAK | K1225: =DATEDIF('DATA PENDUDUK'!$G1225,TODAY(),"Y")& " TAHUN" -> 3 TAHUN | L1225: RT 08
A1226: =IF(D1226="","",ROW()-3) -> 1223 | B1226: 9109162010160011 | C1226: 9404164507230001 | D1226: ARSYILA SAVINA PUTRI | E1226: PEREMPUAN | F1226: TIMIKA | G1226: 45112 | H1226: ISLAM | I1226: BELUM/TIDAK BEKERJA | J1226: ANAK | K1226: =DATEDIF('DATA PENDUDUK'!$G1226,TODAY(),"Y")& " TAHUN" -> 2 TAHUN | L1226: RT 08
... A1235: =IF(D1235="","",ROW()-3) -> 1232 | B1235: 9109162103190015 | C1235: 5206153003920001 | D1235: SURAIDIN | E1235: LAKI-LAKI | F1235: GOWA | G1235: 33693 | H1235: ISLAM | I1235: TENTARA NASIONAL INDONESIA (TNI) | J1235: KEPALA KELUARGA | K1235: =DATEDIF('DATA PENDUDUK'!$G1235,TODAY(),"Y")& " TAHUN" -> 33 TAHUN | L1235: RT 08
A1236: =IF(D1236="","",ROW()-3) -> 1233 | B1236: 9109162103190015 | C1236: 5315054308820003 | D1236: ENDANG MAWARTI | E1236: PEREMPUAN | G1236: 30166 | H1236: ISLAM | I1236: MENGURUS RUMAH TANGGA | J1236: ISTRI | K1236: =DATEDIF('DATA PENDUDUK'!$G1236,TODAY(),"Y")& " TAHUN" -> 42 TAHUN | L1236: RT 08
A1237: =IF(D1237="","",ROW()-3) -> 1234 | B1237: 9109162103190015 | C1237: 5206122212040001 | D1237: RIZAL AF JANUR RAHMAN | E1237: LAKI-LAKI | G1237: 38039 | H1237: ISLAM | I1237: BELUM/TIDAK BEKERJA | J1237: FAMILI LAIN | K1237: =DATEDIF('DATA PENDUDUK'!$G1237,TODAY(),"Y")& " TAHUN" -> 21 TAHUN | L1237: RT 08
A1238: =IF(D1238="","",ROW()-3) -> 1235 | B1238: 9109032307180001 | C1238: 8203052602880001 | D1238: SELVIANUS SUBANG | E1238: LAKI-LAKI | F1238: TOBELO | G1238: 32199 | H1238: KATHOLIK | I1238: TENTARA NASIONAL INDONESIA (TNI) | J1238: KEPALA KELUARGA | K1238: =DATEDIF('DATA PENDUDUK'!$G1238,TODAY(),"Y")& " TAHUN" -> 37 TAHUN | L1238: RT 08
A1239: =IF(D1239="","",ROW()-3) -> 1236 | B1239: 9109032307180001 | C1239: 8207045902850001 | D1239: YOHANA LISNAWATI MEREK | E1239: PEREMPUAN | F1239: MOROTAI | G1239: 31097 | H1239: KATHOLIK | I1239: PEGAWAI NEGERI SIPIL (PNS) | J1239: ISTRI | K1239: =DATEDIF('DATA PENDUDUK'!$G1239,TODAY(),"Y")& " TAHUN" -> 40 TAHUN | L1239: RT 08
A1240: =IF(D1240="","",ROW()-3) -> 1237 | B1240: 9109032307180001 | C1240: 8203057107130001 | D1240: ASTHY JELOVESYA SUBANG | E1240: PEREMPUAN | F1240: TOBELO | G1240: 41486 | H1240: KATHOLIK | I1240: BELUM/TIDAK BEKERJA | J1240: ANAK | K1240: =DATEDIF('DATA PENDUDUK'!$G1240,TODAY(),"Y")& " TAHUN" -> 11 TAHUN | L1240: RT 08
A1241: =IF(D1241="","",ROW()-3) -> 1238 | B1241: 9109032307180001 | C1241: 9109031901170002 | D1241: JUAN ORGILIVE SUBANG | E1241: LAKI-LAKI | F1241: TIMIKA | G1241: 42754 | H1241: KATHOLIK | I1241: BELUMTIDAK BEKERJA | J1241: ANAK | K1241: =DATEDIF('DATA PENDUDUK'!$G1241,TODAY(),"Y")& " TAHUN" -> 8 TAHUN | L1241: RT 08
A1242: =IF(D1242="","",ROW()-3) -> 1239 | B1242: 9109032307180001 | C1242: 9404031905230001 | D1242: CRISPINUS CANELO MILES SUBANG | E1242: LAKI-LAKI | F1242: TOBELO | G1242: 45065 | H1242: KATHOLIK | I1242: BELUMTIDAK BEKERJA | J1242: ANAK | K1242: =DATEDIF('DATA PENDUDUK'!$G1242,TODAY(),"Y")& " TAHUN" -> 2 TAHUN | L1242: RT 08
A1243: =IF(D1243="","",ROW()-3) -> 1240 | B1243: 9404161204230003 | C1243: 1219031001960008 | D1243: RIZKY AWALDI SIBURIAN | E1243: LAKI-LAKI | F1243: TANAH TINGGI | G1243: 35074 | H1243: KRISTEN | I1243: TENTARA NASIONAL INDONESIA (TNI) | J1243: KEPALA KELUARGA | K1243: =DATEDIF('DATA PENDUDUK'!$G1243,TODAY(),"Y")& " TAHUN" -> 29 TAHUN | L1243: RT 08
A1244: =IF(D1244="","",ROW()-3) -> 1241 | B1244: 9404161204230003 | C1244: 1272055705950004 | D1244: AGUSTINA MEGAWATY PASARIBU | E1244: PEREMPUAN | G1244: 34846 | H1244: KRISTEN | I1244: BIDAN | J1244: ISTRI | K1244: =DATEDIF('DATA PENDUDUK'!$G1244,TODAY(),"Y")& " TAHUN" -> 30 TAHUN | L1244: RT 08
A1245: =IF(D1245="","",ROW()-3) -> 1242 | B1245: 9109032907190002 | C1245: 1102052106970001 | D1245: DANIEL MARBUN | E1245: LAKI-LAKI | F1245: PARDAMEAN | G1245: 35602 | H1245: KRISTEN | I1245: TENTARA NASIONAL INDONESIA (TNI) | J1245: KEPALA KELUARGA | K1245: =DATEDIF('DATA PENDUDUK'!$G1245,TODAY(),"Y")& " TAHUN" -> 28 TAHUN | L1245: RT 08
A1246: =IF(D1246="","",ROW()-3) -> 1243 | B1246: 9109032907190002 | C1246: 9109016508940001 | D1246: DENNY RISTA NOVITA SILITONGA | E1246: PEREMPUAN | F1246: SURABAYA | G1246: 34571 | H1246: KRISTEN | J1246: ISTRI | K1246: =DATEDIF('DATA PENDUDUK'!$G1246,TODAY(),"Y")& " TAHUN" -> 30 TAHUN | L1246: RT 08
...
